INFO     backend.layers.business.business:business.py:389 {'message': 'ingesting dataset', 'collection_version_id': e9718259-0ad6-410b-ab7e-41e8f212660f, 'url': 'http://fake.url', 'existing_dataset_version_id': None}
INFO     backend.layers.business.business:business.py:389 {'message': 'ingesting dataset', 'collection_version_id': e9718259-0ad6-410b-ab7e-41e8f212660f, 'url': None, 'existing_dataset_version_id': 27501b94-34cb-477f-9696-25ba99310f93}
INFO     processing:process_logic.py:45 Updating processing status
INFO     processing:process_download.py:120 {'message': 'Estimated resource requirements', 'memory_modifier': 3, 'swap_modifier': 0, 'min_vcpu': 2, 'max_vcpu': 96, 'max_swap_memory_MB': 300000, 'memory_per_vcpu': 8000, 'uncompressed_size_MB': <MagicMock name='read_h5ad().n_obs.__mul__().__truediv__()' id='139654767462240'>, 'max_swap': 0, 'memory': 16000, 'vcpus': 2}
INFO     processing:process_download.py:175 {'JobDefinitionName': 'dp-test-ingest-process-b9b83be9-78af-454a-905d-95b654152899', 'Vcpus': 2, 'Memory': 16000, 'LinuxParameters': {'Swappiness': 60, 'MaxSwap': 0}}
INFO     processing:process_logic.py:45 Updating processing status
INFO     processing:logger.py:26 Start create_artifact
INFO     processing:process_logic.py:45 Updating processing status
INFO     processing:process_logic.py:91 Uploaded [b9b83be9-78af-454a-905d-95b654152899/raw.h5ad] to s3://artifact_bucket/b9b83be9-78af-454a-905d-95b654152899/raw.h5ad
INFO     processing:process_logic.py:93 Updated database with raw_h5ad.
INFO     processing:process_logic.py:45 Updating processing status
INFO     processing:logger.py:28 Complete create_artifact
INFO     processing:process_logic.py:45 Updating processing status
ERROR    processing:dataset_metadata_update.py:196 Cannot find labeled H5AD artifact uri for 27501b94-34cb-477f-9696-25ba99310f93.
INFO     processing:process_logic.py:45 Updating processing status
INFO     processing:dataset_metadata_update.py:202 Main: Starting thread for rds update
INFO     processing:process_logic.py:45 Updating processing status
WARNING  rpy2.rinterface_lib.callbacks:callbacks.py:124 R[write to console]: Error in gzfile(file, "rb") : cannot open the connection

WARNING  rpy2.rinterface_lib.callbacks:callbacks.py:124 R[write to console]: In addition: 
WARNING  rpy2.rinterface_lib.callbacks:callbacks.py:124 R[write to console]: Warning message:

WARNING  rpy2.rinterface_lib.callbacks:callbacks.py:124 R[write to console]: In gzfile(file, "rb") :
WARNING  rpy2.rinterface_lib.callbacks:callbacks.py:124 R[write to console]: 
 
WARNING  rpy2.rinterface_lib.callbacks:callbacks.py:124 R[write to console]:  cannot open compressed file 'local.h5ad', probable reason 'No such file or directory'

INFO     processing:process_logic.py:45 Updating processing status